<mujoco model="so_arm100">
  <compiler angle="radian" />

  <option cone="elliptic" impratio="10" />

  <asset>
    <material name="white" rgba="0.5 0.5 0.5 1" />
    <material name="black" rgba="0.1 0.1 0.1 1" />
    <material name="metal" rgba="0.75 0.75 0.78 1" specular="0.8" shininess="0.6" reflectance="0.3" />

    <mesh name="Base" file="trs_so_arm100/Base.stl" />
    <mesh name="Base_Motor" file="trs_so_arm100/Base_Motor.stl" />
    <mesh name="Rotation_Pitch" file="trs_so_arm100/Rotation_Pitch.stl" />
    <mesh name="Rotation_Pitch_Motor" file="trs_so_arm100/Rotation_Pitch_Motor.stl" />
    <mesh name="Upper_Arm" file="trs_so_arm100/Upper_Arm.stl" />
    <mesh name="Upper_Arm_Motor" file="trs_so_arm100/Upper_Arm_Motor.stl" />
    <mesh name="Lower_Arm" file="trs_so_arm100/Lower_Arm.stl" />
    <mesh name="Lower_Arm_Motor" file="trs_so_arm100/Lower_Arm_Motor.stl" />
    <mesh name="Wrist_Pitch_Roll" file="trs_so_arm100/Wrist_Pitch_Roll.stl" />
    <mesh name="Wrist_Pitch_Roll_Motor" file="trs_so_arm100/Wrist_Pitch_Roll_Motor.stl" />
    <mesh name="Fixed_Jaw" file="trs_so_arm100/Fixed_Jaw.stl" />
    <mesh name="Fixed_Jaw_Motor" file="trs_so_arm100/Fixed_Jaw_Motor.stl" />
    <mesh name="Fixed_Jaw_Collision_1" file="trs_so_arm100/Fixed_Jaw_Collision_1.stl" />
    <mesh name="Fixed_Jaw_Collision_2" file="trs_so_arm100/Fixed_Jaw_Collision_2.stl" />
    <mesh name="Moving_Jaw" file="trs_so_arm100/Moving_Jaw.stl" />
    <mesh name="Moving_Jaw_Collision_1" file="trs_so_arm100/Moving_Jaw_Collision_1.stl" />
    <mesh name="Moving_Jaw_Collision_2" file="trs_so_arm100/Moving_Jaw_Collision_2.stl" />
    <mesh name="Moving_Jaw_Collision_3" file="trs_so_arm100/Moving_Jaw_Collision_3.stl" />
  </asset>

  <default>
    <default class="so_arm100">
      <joint frictionloss="0.1" armature="0.1" />
      <position kp="50" dampratio="1" forcerange="-3.5 3.5" />
      <default class="Rotation">
        <joint axis="0 1 0" range="-1.92 1.92" />
      </default>
      <default class="Pitch">
        <joint axis="1 0 0" range="-3.32 0.174" />
      </default>
      <default class="Elbow">
        <joint axis="1 0 0" range="-0.174 3.14" />
      </default>
      <default class="Wrist_Pitch">
        <joint axis="1 0 0" range="-1.66 1.66" />
      </default>
      <default class="Wrist_Roll">
        <!-- range: 最小 最大 (弧度)。原 -2.79~2.79≈±160°，可按需修改 -->
        <joint axis="0 1 0" range="-3.14 3.14" />
      </default>
      <default class="Jaw">
        <joint axis="0 0 1" range="-0.174 1.75" />
      </default>
      <default class="visual">
        <geom type="mesh" contype="0" conaffinity="0" density="0" group="2" material="white" />
        <default class="motor_visual">
          <geom material="black" />
        </default>
      </default>
      <default class="collision">
        <geom group="3" type="mesh" material="white" />
        <default class="finger_collision">
          <geom type="box" solimp="2 1 0.01" solref="0.01 1" friction="1 0.005 0.0001" />
        </default>
      </default>
    </default>
  </default>

  <worldbody>
    <!-- Base rear edge aligned with table back edge: y smaller = toward back of table -->
    <body name="Base" childclass="so_arm100" pos="0 0.235 0" euler="0 0 3.14159">
      <geom type="mesh" mesh="Base" class="visual" />
      <geom type="mesh" mesh="Base_Motor" class="motor_visual" />
      <geom type="mesh" mesh="Base" class="collision" />
      <body name="Rotation_Pitch" pos="0 -0.0452 0.0165" quat="0.707105 0.707108 0 0">
        <inertial pos="-9.07886e-05 0.0590972 0.031089" quat="0.363978 0.441169 -0.623108 0.533504"
          mass="0.119226"
          diaginertia="5.94278e-05 5.89975e-05 3.13712e-05" />
        <joint name="Rotation" class="Rotation" />
        <geom type="mesh" mesh="Rotation_Pitch" class="visual" />
        <geom type="mesh" mesh="Rotation_Pitch_Motor" class="motor_visual" />
        <geom type="mesh" mesh="Rotation_Pitch" class="collision" />
        <body name="Upper_Arm" pos="0 0.1025 0.0306" euler="1.57079 0 0">
          <inertial pos="-1.72052e-05 0.0701802 0.00310545"
            quat="0.50104 0.498994 -0.493562 0.50632" mass="0.162409"
            diaginertia="0.000213312 0.000167164 7.01522e-05" />
          <joint name="Pitch" class="Pitch" />
          <geom type="mesh" mesh="Upper_Arm" class="visual" />
          <geom type="mesh" mesh="Upper_Arm_Motor" class="motor_visual" />
          <geom type="mesh" mesh="Upper_Arm" class="collision" />
          <body name="Lower_Arm" pos="0 0.11257 0.028" euler="-1.57079 0 0">
            <inertial pos="-0.00339604 0.00137796 0.0768007"
              quat="0.701995 0.0787996 0.0645626 0.704859"
              mass="0.147968" diaginertia="0.000138803 0.000107748 4.84242e-05" />
            <joint name="Elbow" class="Elbow" />
            <geom type="mesh" mesh="Lower_Arm" class="visual" />
            <geom type="mesh" mesh="Lower_Arm_Motor" class="motor_visual" />
            <geom type="mesh" mesh="Lower_Arm" class="collision" />
            <body name="Wrist_Pitch_Roll" pos="0 0.0052 0.1349" euler="-1.57079 0 0">
              <inertial pos="-0.00852653 -0.0352279 -2.34622e-05"
                quat="-0.0522806 0.705235 0.0549524 0.704905"
                mass="0.0661321" diaginertia="3.45403e-05 2.39041e-05 1.94704e-05" />
              <joint name="Wrist_Pitch" class="Wrist_Pitch" />
              <geom type="mesh" mesh="Wrist_Pitch_Roll" class="visual" />
              <geom type="mesh" mesh="Wrist_Pitch_Roll_Motor" class="motor_visual" />
              <geom type="mesh" mesh="Wrist_Pitch_Roll" class="collision" />
              <!-- euler Y: 原 1.57079(90°) → -1.57079(-90°)，使 Wrist_Roll=0 时末端多转 180° -->
                <body name="Fixed_Jaw" pos="0 -0.0601 0" euler="0 -1.57079 0">
                <inertial pos="0.00552377 -0.0280167 0.000483583"
                  quat="0.41836 0.620891 -0.350644 0.562599"
                  mass="0.0929859" diaginertia="5.03136e-05 4.64098e-05 2.72961e-05" />
                <joint name="Wrist_Roll" class="Wrist_Roll" />
                <geom type="mesh" mesh="Fixed_Jaw" class="visual" />
                <geom type="mesh" mesh="Fixed_Jaw_Motor" class="motor_visual" />
                <geom type="mesh" mesh="Fixed_Jaw_Collision_1" class="collision" />
                <geom type="mesh" mesh="Fixed_Jaw_Collision_2" class="collision" />
                <geom class="finger_collision" name="fixed_jaw_pad_1" size="0.001 0.005 0.004"
                  pos="0.0089 -0.1014 0" />
                <geom class="finger_collision" name="fixed_jaw_pad_2" size="0.001 0.005 0.006"
                  pos="0.0109 -0.0914 0" />
                <geom class="finger_collision" name="fixed_jaw_pad_3" size="0.001 0.01 0.007"
                  pos="0.0126 -0.0768 0" />
                <geom class="finger_collision" name="fixed_jaw_pad_4" size="0.001 0.01 0.008"
                  pos="0.0143 -0.0572 0" />
                <body name="vx300s_left/camera_focus" pos="0.0 -.06 0">
                  <site pos="0 0 0" size="0.01" type="sphere" name="left_cam_focus"
                    rgba="0 0 1 0" />
                  <site name="ee_site" pos="0 0 0" />
                  <!-- Web camera at gripper: eye-in-hand view -->
                  <camera name="wrist_webcam" pos="0 0.04 0.025" fovy="75" xyaxes="1 0 0 0 0.208 -0.978" />
                </body>
                
                <!-- <camera name="left_wrist" pos="0 .0 0.55" fovy="10" mode="targetbody" target="left_wrist_lookat" /> -->
                <camera name="left_wrist" mode="fixed" pos="0 0.3 0.55" euler="-0.64 0 0" fovy="10" resolution="640 480" />
                <body name="Moving_Jaw" pos="-0.0202 -0.0244 0"
                  quat="1.34924e-11 -3.67321e-06 1 -3.67321e-06">
                  <inertial pos="-0.00161745 -0.0303473 0.000449646"
                    quat="0.696562 0.716737 -0.0239844 -0.0227026"
                    mass="0.0202444" diaginertia="1.11265e-05 8.99651e-06 2.99548e-06" />
                  <joint name="Jaw" class="Jaw" />

                  <geom type="mesh" mesh="Moving_Jaw" class="visual" />
                  <geom type="mesh" mesh="Moving_Jaw_Collision_1" class="collision" />
                  <geom type="mesh" mesh="Moving_Jaw_Collision_2" class="collision" />
                  <geom type="mesh" mesh="Moving_Jaw_Collision_3" class="collision" />
                  <geom class="finger_collision" name="moving_jaw_pad_1" size="0.001 0.005 0.004"
                    pos="-0.0113 -0.077 0" />
                  <geom class="finger_collision" name="moving_jaw_pad_2" size="0.001 0.005 0.006"
                    pos="-0.0093 -0.067 0" />
                  <geom class="finger_collision" name="moving_jaw_pad_3" size="0.001 0.01 0.006"
                    pos="-0.0073 -0.055 0" />
                  <geom class="finger_collision" name="moving_jaw_pad_4" size="0.001 0.01 0.008"
                    pos="-0.0073 -0.035 0" />
                </body>
              </body>
            </body>
          </body>
        </body>
      </body>
    </body>
  </worldbody>

  <actuator>
    <position class="Rotation" name="Rotation" joint="Rotation" inheritrange="1" />
    <position class="Pitch" name="Pitch" joint="Pitch" inheritrange="1" />
    <position class="Elbow" name="Elbow" joint="Elbow" inheritrange="1" />
    <position class="Wrist_Pitch" name="Wrist_Pitch" joint="Wrist_Pitch" inheritrange="1" />
    <position class="Wrist_Roll" name="Wrist_Roll" joint="Wrist_Roll" inheritrange="1" />
    <position class="Jaw" name="Jaw" joint="Jaw" inheritrange="1" />
  </actuator>

  <contact>
    <exclude body1="Base" body2="Rotation_Pitch" />
  </contact>

</mujoco>
